Workbook

Sheet Tarefas
A1: # | B1: Data Início | C1: Data Fim | D1: Área | E1: Categoria | F1: Módulo | G1: Descrição | H1: Story Points
A2: 1. Setup e Infraestrutura
A3: 1 | B3: 2026-04-07 | C3: 2026-04-09 | D3: App | E3: Feature | F3: Infra mobile | G3: Fix Android release device env selection, handle reinstall, adicionar MS_CHAT_URL para Socket.IO (alertport-app) | H3: 3
A4: 2 | B4: 2026-04-16 | C4: 2026-04-16 | D4: Frontend | E4: DevOps | F4: Build/Deploy | G4: Scaffolding inicial Next.js 16 (App Router) + estrutura de pastas + api-client + socket client | H4: 8
A5: 3 | B5: 2026-04-16 | C5: 2026-04-16 | D5: Frontend | E5: DevOps | F5: Build/Deploy | G5: Configuração Vercel HML (admin-alertport-hml) + scripts/deploy.sh + projetos separados prod/hml | H5: 3
A6: 4 | B6: 2026-04-16 | C6: 2026-04-16 | D6: Frontend | E6: DevOps | F6: Build/Deploy | G6: Templates .env (example/hml/production) alinhados com endpoints HML shieldgo | H6: 2
A7: 2. Autenticação e Cadastro
A8: 5 | B8: 2026-04-16 | C8: 2026-04-16 | D8: Frontend | E8: Feature | F8: Auth | G8: Fluxo de login com persistência de sessão, guard de rota e auto-logout em token expirado | H8: 5
A9: 6 | B9: 2026-04-16 | C9: 2026-04-16 | D9: Frontend | E9: Fix | F9: Auth | G9: Fix infinite loop em auth + remover título legacy na tela de login | H9: 1
A10: 7 | B10: 2026-04-16 | C10: 2026-04-16 | D10: Frontend | E10: Feature | F10: Auth | G10: Fluxo completo de recuperação de senha (3 passos: email, código, nova senha) | H10: 3
A11: 8 | B11: 2026-04-17 | C11: 2026-04-17 | D11: Frontend | E11: Feature | F11: Signup | G11: Self-signup multi-step (dados pessoais + empresa) + tela /register dedicada | H11: 5
A12: 9 | B12: 2026-04-17 | C12: 2026-04-17 | D12: Frontend | E12: Feature | F12: Signup | G12: Página /activate com código manual + ativação via link (one-click) em Suspense boundary | H12: 3
A13: 10 | B13: 2026-04-17 | C13: 2026-04-17 | D13: Backend | E13: Feature | F13: Signup | G13: ms-user: self-signup + email de ativação + activation via native Mongo driver (bypass hp-shield-crud) | H13: 5
A14: 11 | B14: 2026-04-17 | C14: 2026-04-17 | D14: Backend | E14: Feature | F14: Signup | G14: Link-based activation (botão one-click) + email premium AlertPort + token-safe activate | H14: 3
A15: 12 | B15: 2026-04-17 | C15: 2026-04-17 | D15: Frontend | E15: Feature | F15: Signup | G15: Modais Premium de Termos de Uso + Política de Privacidade no step 2 do signup | H15: 2
A16: 13 | B16: 2026-04-17 | C16: 2026-04-17 | D16: Frontend | E16: Feature | F16: Signup | G16: Validação de CPF (11 dígitos) + CNPJ (14) com checksum + CNPJ alfanumérico (IN RFB 2.229/2024) com testes | H16: 3
A17: 14 | B17: 2026-04-17 | C17: 2026-04-17 | D17: Frontend | E17: Feature | F17: Signup | G17: Seletor de timezone + password policy + ícone mostrar/ocultar senha | H17: 2
A18: 3. Trial e Plano
A19: 15 | B19: 2026-04-17 | C19: 2026-04-17 | D19: Backend | E19: Feature | F19: Trial/Plan | G19: Trial centralizado end-to-end: plan-config.js (catálogo PLANS + FEATURES) + access-policy-service (canCreate, canUseFeature, getContext) | H19: 8
A20: 16 | B20: 2026-04-17 | C20: 2026-04-17 | D20: Backend | E20: Feature | F20: Trial/Plan | G20: Endpoints trial (context, status, history, start, extend, expire, convert) + plan (features, limits) | H20: 5
A21: 17 | B21: 2026-04-17 | C21: 2026-04-17 | D21: Frontend | E21: Feature | F21: Trial/Plan | G21: Trial mode UI completo: banner, badge, TrialProvider, gating de botões de criação (GatedCreateButton), modal de expirado | H21: 5
A22: 18 | B22: 2026-04-17 | C22: 2026-04-17 | D22: Frontend | E22: Feature | F22: Trial/Plan | G22: Mid-session refresh + interceptor 503 + i18n de features + CTA role-gated (só ADMIN vê upgrade) | H22: 3
A23: 4. CRUDs principais
A24: 19 | B24: 2026-04-16 | C24: 2026-04-18 | D24: Frontend | E24: Feature | F24: Users | G24: CRUD de Usuários (sistema): listagem, filtros, form de criação/edição, photo upload, preserve hierarquia em edit | H24: 5
A25: 20 | B25: 2026-04-16 | C25: 2026-04-20 | D25: Frontend | E25: Feature | F25: Collaborators | G25: CRUD de Colaboradores (vigias/supervisores): schema completo, address/CEP autofill, matrícula visível + placeholder auto-gerado | H25: 5
A26: 21 | B26: 2026-04-16 | C26: 2026-04-17 | D26: Frontend | E26: Feature | F26: Clients | G26: CRUD de Clientes: listagem, form com account+cascade, phone mask, remoção de upload de logo (crash fix) | H26: 3
A27: 22 | B27: 2026-04-16 | C27: 2026-04-16 | D27: Frontend | E27: Feature | F27: Sites | G27: CRUD de Postos com diálogo de QR Code (geração do QR único para vinculação do app no Posto) | H27: 5
A28: 23 | B28: 2026-04-16 | C28: 2026-04-16 | D28: Frontend | E28: Feature | F28: Equipment | G28: CRUD de Equipamentos com cascade account→client→site e filtros de hierarquia | H28: 3
A29: 24 | B29: 2026-04-16 | C29: 2026-04-16 | D29: Frontend | E29: Feature | F29: Company | G29: Tela de Configurações da Empresa (/company) com /me endpoint + campos legacy + CEP autofill compartilhado | H29: 3
A30: 25 | B30: 2026-04-16 | C30: 2026-04-16 | D30: Frontend | E30: Feature | F30: Shared | G30: Hierarchy cascade em todo o app: useAccountsLookup / useClientsLookup / useSitesLookup com cascade estrito | H30: 5
A31: 26 | B31: 2026-04-17 | C31: 2026-04-17 | D31: Frontend | E31: Fix | F31: Shared | G31: Sanitização de payloads + phone mask sweep + password policy + invalidação em cascata após mutation | H31: 3
A32: 27 | B32: 2026-04-17 | C32: 2026-04-17 | D32: Frontend | E32: Fix | F32: Shared | G32: Rejeitar upload de arquivo vazio na fonte + toast explicativo + permitir Axios setar boundary de FormData | H32: 2
A33: 5. Dashboard e Monitor
A34: 28 | B34: 2026-04-16 | C34: 2026-04-19 | D34: Frontend | E34: Feature | F34: Dashboard | G34: Dashboard KPIs (total alertas, pendentes, respondidos, perdidos, equipamentos/colaboradores ativos) com React Query | H34: 3
A35: 29 | B35: 2026-04-17 | C35: 2026-04-19 | D35: Frontend | E35: Feature | F35: Monitor | G35: Monitor de Alertas em tempo real (socket + firestore) com 5 KPIs e filtros | H35: 8
A36: 30 | B36: 2026-04-19 | C36: 2026-04-19 | D36: Frontend | E36: Feature | F36: Monitor | G36: Máquina de estados de ownership de atendimento (available→in_progress→closed) com transições guardadas | H36: 5
A37: 31 | B37: 2026-04-19 | C37: 2026-04-19 | D37: Frontend | E37: Tests | F37: Monitor | G37: Cobertura exaustiva da máquina de estados (attendance-state.ts) com todos os cenários de ownership | H37: 3
A38: 32 | B38: 2026-04-19 | C38: 2026-04-19 | D38: Frontend | E38: Feature | F38: SOS | G38: SOS Notifications globais (aparecem em qualquer tela) com one-click auto-claim e banner fixo z-80 | H38: 5
A39: 33 | B39: 2026-04-20 | C39: 2026-04-20 | D39: Frontend | E39: Feature | F39: SOS | G39: Alarme sonoro de 2 segundos em chegada de SOS + integração com autoplay policy | H39: 2
A40: 6. Agendamento de Alertas
...

Sheet Resumo
A1: AlertPort - Levantamento de Esforço
A3: Período | B3: Início: 2026-04-07 (app) / 2026-04-16 (web)
A4: Conclusão: 2026-04-20 (HML)
A6: Totais por Área
A7: Área | B7: Tarefas | C7: Story Points | D7: % Tarefas | E7: % SP
A8: Backend | B8: =COUNTIF(Tarefas!D2:D95,"Backend") | C8: =SUMIF(Tarefas!D2:D95,"Backend",Tarefas!H2:H95) | D8: =B8/B11 | E8: =C8/C11
A9: Frontend | B9: =COUNTIF(Tarefas!D2:D95,"Frontend") | C9: =SUMIF(Tarefas!D2:D95,"Frontend",Tarefas!H2:H95) | D9: =B9/B11 | E9: =C9/C11
A10: App | B10: =COUNTIF(Tarefas!D2:D95,"App") | C10: =SUMIF(Tarefas!D2:D95,"App",Tarefas!H2:H95) | D10: =B10/B11 | E10: =C10/C11
A11: TOTAL | B11: =SUM(B8:B10) | C11: =SUM(C8:C10) | D11: =SUM(D8:D10) | E11: =SUM(E8:E10)
A13: Totais por Categoria
A14: Categoria | B14: Tarefas | C14: Story Points | D14: % Tarefas | E14: % SP
A15: Feature | B15: =COUNTIF(Tarefas!E2:E95,"Feature") | C15: =SUMIF(Tarefas!E2:E95,"Feature",Tarefas!H2:H95) | D15: =B15/B11 | E15: =C15/C11
A16: Fix | B16: =COUNTIF(Tarefas!E2:E95,"Fix") | C16: =SUMIF(Tarefas!E2:E95,"Fix",Tarefas!H2:H95) | D16: =B16/B11 | E16: =C16/C11
A17: Refactor | B17: =COUNTIF(Tarefas!E2:E95,"Refactor") | C17: =SUMIF(Tarefas!E2:E95,"Refactor",Tarefas!H2:H95) | D17: =B17/B11 | E17: =C17/C11
A18: Tests | B18: =COUNTIF(Tarefas!E2:E95,"Tests") | C18: =SUMIF(Tarefas!E2:E95,"Tests",Tarefas!H2:H95) | D18: =B18/B11 | E18: =C18/C11
A19: DevOps | B19: =COUNTIF(Tarefas!E2:E95,"DevOps") | C19: =SUMIF(Tarefas!E2:E95,"DevOps",Tarefas!H2:H95) | D19: =B19/B11 | E19: =C19/C11
A22: Distribuição de Story Points
A23: Story Points | B23: Qtd Tarefas | C23: Total SP | D23: % Tarefas | E23: % SP
A24: 1 | B24: =COUNTIF(Tarefas!H2:H95,1) | C24: =B24*1 | D24: =B24/B11 | E24: =C24/C11
A25: 2 | B25: =COUNTIF(Tarefas!H2:H95,2) | C25: =B25*2 | D25: =B25/B11 | E25: =C25/C11
A26: 3 | B26: =COUNTIF(Tarefas!H2:H95,3) | C26: =B26*3 | D26: =B26/B11 | E26: =C26/C11
A27: 5 | B27: =COUNTIF(Tarefas!H2:H95,5) | C27: =B27*5 | D27: =B27/B11 | E27: =C27/C11
A28: 8 | B28: =COUNTIF(Tarefas!H2:H95,8) | C28: =B28*8 | D28: =B28/B11 | E28: =C28/C11
A29: 13 | B29: =COUNTIF(Tarefas!H2:H95,13) | C29: =B29*13 | D29: =B29/B11 | E29: =C29/C11
A31: Notas
A32: • Story Points usam Fibonacci (1, 2, 3, 5, 8, 13) refletindo complexidade relativa, não horas.
A33: • 1 = trivial (poucas horas) · 2 = pequeno · 3 = moderado · 5 = médio · 8 = grande · 13 = muito grande.
A34: • Áreas: Backend = shieldgo-microservices (ms-user, ms-company, ms-chat, api-gateway). Frontend = alertport-admin-web (Next.js). App = alertport-app (React Native).
A35: • Tarefas aqui são consolidações de múltiplos commits relacionados do mesmo escopo. A aba Tarefas tem linha detalhada por escopo.
A36: • Período coberto: 2026-04-07 (primeiros commits no app) a 2026-04-20 (deploy do módulo de gestão de módulos em HML).
